/**
 * helper function so error can pass to next middleware
 * @param {function} fn
 */
const catchAsync = (fn) => (req, res, next) => {
  Promise.resolve(fn(req, res, next)).catch((err) => next(err));
};

module.exports = catchAsync;
